2024-05-21 00:23:31,519 INFO    StreamThr :952399 [internal.py:wandb_internal():85] W&B internal server running at pid: 952399, started at: 2024-05-21 00:23:31.517949
2024-05-21 00:23:31,522 DEBUG   HandlerThread:952399 [handler.py:handle_request():158] handle_request: status
2024-05-21 00:23:31,534 INFO    WriterThread:952399 [datastore.py:open_for_write():87] open: /home/jeehyun/coursework/DL/MeOw-LO/wandb/run-20240521_002331-i3w5zter/run-i3w5zter.wandb
2024-05-21 00:23:31,535 DEBUG   SenderThread:952399 [sender.py:send():378] send: header
2024-05-21 00:23:31,545 DEBUG   SenderThread:952399 [sender.py:send():378] send: run
2024-05-21 00:23:31,982 ERROR   SenderThread:952399 [internal_api.py:execute():344] 404 response executing GraphQL.
2024-05-21 00:23:31,983 ERROR   SenderThread:952399 [internal_api.py:execute():345] {"errors":[{"message":"project not found","path":["upsertBucket"]}],"data":{"upsertBucket":null}}
2024-05-21 00:23:31,983 ERROR   SenderThread:952399 [sender.py:send_run():970] It appears that you do not have permission to access the requested resource. Please reach out to the project owner to grant you access. If you have the correct permissions, verify that there are no issues with your networking setup.(Error 404: Not Found)
Traceback (most recent call last):
  File "/home/jeehyun/.miniconda3/envs/dl/lib/python3.12/site-packages/wandb/sdk/lib/retry.py", line 131, in __call__
    result = self._call_fn(*args, **kwargs)
             ^^^^^^^^^^^^^^^^^^^^^^^^^^^^^^
  File "/home/jeehyun/.miniconda3/envs/dl/lib/python3.12/site-packages/wandb/sdk/internal/internal_api.py", line 340, in execute
    return self.client.execute(*args, **kwargs)  # type: ignore
           ^^^^^^^^^^^^^^^^^^^^^^^^^^^^^^^^^^^^
  File "/home/jeehyun/.miniconda3/envs/dl/lib/python3.12/site-packages/wandb/vendor/gql-0.2.0/wandb_gql/client.py", line 52, in execute
    result = self._get_result(document, *args, **kwargs)
             ^^^^^^^^^^^^^^^^^^^^^^^^^^^^^^^^^^^^^^^^^^^
  File "/home/jeehyun/.miniconda3/envs/dl/lib/python3.12/site-packages/wandb/vendor/gql-0.2.0/wandb_gql/client.py", line 60, in _get_result
    return self.transport.execute(document, *args, **kwargs)
           ^^^^^^^^^^^^^^^^^^^^^^^^^^^^^^^^^^^^^^^^^^^^^^^^^
  File "/home/jeehyun/.miniconda3/envs/dl/lib/python3.12/site-packages/wandb/sdk/lib/gql_request.py", line 59, in execute
    request.raise_for_status()
  File "/home/jeehyun/.miniconda3/envs/dl/lib/python3.12/site-packages/requests/models.py", line 1021, in raise_for_status
    raise HTTPError(http_error_msg, response=self)
requests.exceptions.HTTPError: 404 Client Error: Not Found for url: https://api.wandb.ai/graphql

During handling of the above exception, another exception occurred:

Traceback (most recent call last):
  File "/home/jeehyun/.miniconda3/envs/dl/lib/python3.12/site-packages/wandb/sdk/internal/sender.py", line 968, in send_run
    server_run = self._init_run(run, config_value_dict)
                 ^^^^^^^^^^^^^^^^^^^^^^^^^^^^^^^^^^^^^^
  File "/home/jeehyun/.miniconda3/envs/dl/lib/python3.12/site-packages/wandb/sdk/internal/sender.py", line 1013, in _init_run
    server_run, inserted, server_messages = self._api.upsert_run(
                                            ^^^^^^^^^^^^^^^^^^^^^
  File "/home/jeehyun/.miniconda3/envs/dl/lib/python3.12/site-packages/wandb/apis/normalize.py", line 73, in wrapper
    raise err
  File "/home/jeehyun/.miniconda3/envs/dl/lib/python3.12/site-packages/wandb/apis/normalize.py", line 41, in wrapper
    return func(*args, **kwargs)
           ^^^^^^^^^^^^^^^^^^^^^
  File "/home/jeehyun/.miniconda3/envs/dl/lib/python3.12/site-packages/wandb/sdk/internal/internal_api.py", line 2188, in upsert_run
    response = self.gql(
               ^^^^^^^^^
  File "/home/jeehyun/.miniconda3/envs/dl/lib/python3.12/site-packages/wandb/sdk/internal/internal_api.py", line 312, in gql
    ret = self._retry_gql(
          ^^^^^^^^^^^^^^^^
  File "/home/jeehyun/.miniconda3/envs/dl/lib/python3.12/site-packages/wandb/sdk/lib/retry.py", line 147, in __call__
    retry_timedelta_triggered = check_retry_fn(e)
                                ^^^^^^^^^^^^^^^^^
  File "/home/jeehyun/.miniconda3/envs/dl/lib/python3.12/site-packages/wandb/util.py", line 965, in check_retry_fn
    return fallback_retry_fn(e)
           ^^^^^^^^^^^^^^^^^^^^
  File "/home/jeehyun/.miniconda3/envs/dl/lib/python3.12/site-packages/wandb/util.py", line 907, in no_retry_auth
    raise CommError(
wandb.errors.CommError: It appears that you do not have permission to access the requested resource. Please reach out to the project owner to grant you access. If you have the correct permissions, verify that there are no issues with your networking setup.(Error 404: Not Found)
2024-05-21 00:23:32,154 DEBUG   HandlerThread:952399 [handler.py:handle_request():158] handle_request: shutdown
2024-05-21 00:23:32,155 INFO    HandlerThread:952399 [handler.py:finish():882] shutting down handler
2024-05-21 00:23:32,545 INFO    WriterThread:952399 [datastore.py:close():296] close: /home/jeehyun/coursework/DL/MeOw-LO/wandb/run-20240521_002331-i3w5zter/run-i3w5zter.wandb
2024-05-21 00:23:32,992 INFO    SenderThread:952399 [sender.py:finish():1545] shutting down sender
